Workbook
Name HIT_1: 'Pool Index'!$G$46
Name HIT_19: 'Pool Index'!$R$70
Name PAGE_104_3133: '1928Rail'!$A$102
Name PAGE_104_3133: '1932Rail'!#REF!
Name PAGE_3_7131: '1928Rail'!$A$103
Name PAGE_3_7131: '1932Rail'!#REF!
Name PAGE_4_7131: '1928Rail'!#REF!
Name PAGE_4_7131: '1932Rail'!#REF!

Sheet Pool Index
A1: PoolID | B1: Technology | C1: Contract Location | D1: Collected Data? | E1: Given to RA | F1: Completed (X=yes, blank=no) | G1: Case Title(s) | H1: Vaughan Ref. | I1: Type of Document(s) | J1: Year pool formed | K1: First Litigation | L1: Final Litigation | M1: Grantbacks | N1: Foreign Firms | O1: Compulsory Licensing | P1: Licensees | Q1: Prior Litigation | R1: Notes
A2: 1919Equi | B2: Electrical Equipment | C2: NAR New York | D2: Y | F2: X | G2: United States v. General Electric Co., CCH 1952-53 Trade Cases 67,585 (D.C.N.J. Civil No. 45-75-C; Complaint, 1945; Final Consent Judgment, 1953). | H2: 164 | I2: CO, FJ | J2: 1919 | L2: 1953 | N2: Y | O2: RR | P2: 0 | R2: 600+ patents RR
A3: 1921Cast | B3: Cast Iron Pipes | C3: NAR New York | D3: Y | F3: X | G3: United States v. United States Pipe and Foundry Co., CCH 1948-49 Trade Cases 62,285 (D.N.J. Civil No. 10772; Complaint, 1947; Consent Decree, 1948). | H3: 123 | I3: CO, FJ | J3: 1929 | K3: 1947 | L3: 1948 | N3: N | O3: DP | P3: 4
A4: 1924Brak | B4: Braking Systems | C4: NAR New York | D4: Y | F4: X | G4: United States v. Bendix Aviation Corp., Westinghouse Air Brake Co., et al., CCH 1948-49 Trade Cases 62,349 (S.D.N.Y. Civil No. 44-284; Complaint , 1947; Consent Judgment re Westinghouse, 1948). | H4: 96-97 | I4: CO, FJ, LA | J4: 1924 | K4: 1947 | L4: 1948 | N4: N | O4: RF, RR | P4: 21
A5: 1924Sand | B5: Sand Spun Pipes | C5: NAR New York | D5: Y | F5: X | G5: United States v. Sand Spun Patents Corp., 1948-1949 Trade Cases 62,462 (D.N.J. Civil No. 125-49; Complaint, 1949; Consent Judgment, 1949). | H5: 123-24 | I5: CO, FJ | J5: 1924 | L5: 1949 | N5: N | O5: DP | P5: 0
A6: 1925Vent | B6: Ventilating Air Filters | C6: NAR Atlanta | D6: Y | F6: X | G6: United States v. American Air Filter Co., CCH 1946-47 Trade Cases 57,492 (W.D. Ky. Civil No. 574; Complaint, 1943; Consent Judgment, 1946). | H6: 92-93 | I6: FJ | J6: 1925 | L6: 1946 | N6: N | O6: DP, RR | P6: 4
A7: 1926Food | B7: Peach Pitting Machinery | C7: NAR San Francisco | D7: Y | F7: X | G7: United States v. Food Machinery and Chemical Corp. (N.D. Calif. Civil No. 29308-G; Complaint, 1949). | H7: 61 | I7: WO | J7: 1926 | L7: 1954 | N7: N | O7: RR | P7: 0
A8: 1927Airc | B8: Air-conditioning Equipment | C8: NAR New York | D8: Y | F8: X | G8: United States v. Auditorium Conditioning Corp., CCH 1944-45 Trade Cases 57,428 (S.D.N.Y. Civil No. 22-200; Complaint, 1943; Final Judgment, 1945). | H8: 55-56 | I8: CO, FJ, LA | J8: 1927 | K8: 1943 | L8: 1945 | N8: N | O8: DP | P8: 7
A9: 1927Flur | B9: Glass Lamps | C9: NAR New York | D9: Y | F9: X | G9: United States v. General Electric Co., Corning Glass Works, et al., CCH 1946-47 Trade Cases 57,448 (D.N.J. Civil No. 2590; Complaint, 1942; Consent Decree re Corning, 1946). | H9: 125-26 | I9: CO, FJ | J9: 1927 | L9: 1954 | N9: Y | O9: RF | P9: 11 | R9: Need to google search for Corning patents
A10: 1928Rail | B10: Rail Joint Bars | C10: NAR Chicago | D10: Y | F10: X | G10: United States v. Rail Joint Co., CCH 1946-47 Trade Cases ¶ 57,469, (N. D. Ill. Civil No. 43-C-1295; Complaint, 1943; Final Judgment, 1944); McKenna Process Company of Illinois, Appellee, v. Blatchford Corporation, Appellant, Gen. No. 9,464, APPELLATE COURT OF ILLINOIS, SECOND DISTRICT, 304 Ill. App. 101; 25 N.E.2d 916; 1940 Ill. App. LEXIS 921. | H10: 55 | I10: CO, FJ | J10: 1928 | L10: 1944 | N10: N | O10: DP | P10: 10 | R10: Think all of the patents are dedicated to public
A11: 1930Cabl | B11: High-Tension Cables | C11: NAR New York | D11: Y | F11: X | G11: United States v. General Cable Corp., CCH 1948-49 Trade Cases 62,300 (S.D.N.Y. Civil No. 40-76; Complaint, 1947; Consent Judgment, 1948). | H11: 58-59 | I11: CO, FJ, LA | J11: 1930 | L11: 1948 | M11: 1 | N11: Y | O11: RR, RF | P11: 0 | Q11: 0
A12: 1930Wate | B12: Water Conditioning Apparatus | C12: NAR New York | D12: Y | F12: X | G12: United States v. The Permutit Company and W. Spencer Robertson, CCH 1950-51 Trade Cases 62,888 (S.D.N.Y. Civil No. 32-394; Complaint, 1945; Consent Judgment, 1951). | H12: 163 | I12: CO, FJ, LA | J12: 1930 | L12: 1951 | M12: 1 | N12: Y | O12: RF, RR | P12: 0 | Q12: 0
A13: 1931Fuel | B13: Fuel Injection Equipment | C13: NAR New York | D13: Y | F13: X | G13: United States v. American Bosch Corp., CCH 1948-49 Trade Cases 62,284 (S.D.N.Y. Civil No. 20-164; Complaint and Consent Decree, Dec. 29, 1942). | H13: 158 | I13: CO, FJ | J13: 1931 | L13: 1942 | M13: 1 | N13: Y | O13: RR | P13: 0 | Q13: 1
A14: 1931Mill | B14: Milling Machines | C14: NAR Chicago | D14: Y | F14: X | G14: United States v. Cincinnati Milling Machine Co., CCH 1953-54 Trade Cases 67,733 (E.D. Mich Civil No. 13401; Complaint and Consent Judgment, April 19, 1954). | H14: 126 | I14: CO, FJ | J14: 1931 | L14: 1954 | N14: N | O14: RR | P14: 2
A15: 1932Phar | B15: Pharmaceuticals | C15: NAR New York | D15: Y | F15: X | G15: United States v. Merck and Co., CCH 1944-45 Trade Cases 57,416 (D.C.N.J. Civil No. 3159; Complaint, 1943; Consent Decree, 1945). | H15: 157-58 | I15: CO, FJ, LA | J15: 1932 | K15: 1943 | L15: 1945 | M15: 1 | N15: Y | O15: RF, DP | P15: 0 | Q15: 0
A16: 1932Rail | B16: Railroad Springs | C16: NAR Chicago | D16: Y | F16: X | G16: United States v. American Locomotive Co., CCH 1945-47 Trade Cases ¶ 57,621 (N.D. Ind. Civil No. 545; Complaint, 1945; Consent Judgment, 1947). | H16: 192 | I16: CO, FJ, LA | J16: 1932 | L16: 1947 | M16: 1 | N16: N | O16: RR, DP | P16: 9 | Q16: 0
A17: 1932Text | B17: Hosiery Machinery | C17: NAR New York | D17: Y | F17: X | G17: United States v. Textile Machine Works, CCH 1950-51 Trade Cases 62,709 (S.D.N.Y. Civil No. 43-671; Complaint, 1947; Fina; Judgment, 1950). | H17: 98 | I17: CO, FJ | J17: 1932 | K17: 1947 | L17: 1950 | M17: 0 | N17: N | O17: RR, DP | P17: 0 | Q17: 0 | R17: Patent pool?
A18: 1933Hydr | B18: Hydraulic Oil Pumps | C18: NADC | D18: N | F18: X | G18: Kobe, Inc. v. Dempsey Pump Co., 198 F.2d 416 (10th Cir. 1952); United States v. Kobe (N.D. Okla. Civil No. 2865; Complaint, 1951); also Civ. No. 2350. | H18: 61 | I18: FJ | J18: 1933 | K18: 1952 | L18: 1952 | M18: 1 | N18: N | P18: 0 | Q18: 0 | R18: ** Final judgments? Did not grant licenses to third parties after 1934.
A19: 1933Mach | B19: Machine Tools | C19: NAR Chicago | D19: Y | F19: X | G19: United States v. Associated Patents, 134 F. Supp. 74 (E.D. Mich., 1955). | H19: 61 | I19: FJ, LA | J19: 1933 | L19: 1955 | M19: 1 | N19: N | P19: 0 | Q19: 0
A20: 1933Phil | B20: Phillips Screws | C20: NAR Chicago | D20: Y | F20: X | G20: United States v. Phillips Screw Co., 1949 Trade Cas. (C.C.H.) ¶62,394 (N.D. Ill.) | H20: 124 | I20: CO, FJ, LA | J20: 1933 | K20: . | L20: 1949 | M20: 1 | N20: N | O20: RR | P20: 28 | Q20: 0
A21: 1934Colo | B21: Color Film | C21: NAR Riverside (LA) | D21: Y | F21: X | G21: United States v. Technicolor, Inc., CCH 1950-51 Trade Cases 2,586 (S.D. Calif. Civil No. 7507-M; Complaint, 1947; Consent Judgments, 1948 and 1950). | H21: 274-75 | I21: CO, LA, FJ | J21: 1934 | L21: 1950 | M21: 1 | N21: N | O21: RF, RR | P21: 0 | Q21: 0
A22: 1934Dry | B22: Dry Ice | C22: NAR New York | D22: Y | F22: X | G22: United States v. The Liquid Carbonic Corp., CCH Trade Cases 67,248 (E.D.N.Y. Civil No. 9179; Complaint, 1948; Final Judgment, 1952). | H22: 98-99 | I22: WO | J22: 1934 | L22: 1952 | M22: 1 | N22: N | O22: RR | P22: 0 | Q22: 0
A23: 1934Elec | B23: Electric Generators | C23: NAR New York | D23: Y | F23: X | G23: United States v. Westinghouse Electric Mfg. Co., CCH Current Trade Cases 67,501 (D.C.N.J. Civil No. 5152; Complaint, 1945; Consent Judgment, 1953). | H23: 163-64 | I23: LA | J23: 1934 | K23: 1953 | L23: 1953 | M23: 1 | N23: Y | O23: DP | P23: 0 | Q23: 0 | R23: ** Photocopy final judgment
A24: 1934Leci | B24: Lecithin | C24: NAR Chicago | D24: Y | F24: X | G24: United States v. American Lecithin Co., CCH 1946-47 Trade Cases 57,542 (N.D. Ohio Civil No. 24115; Complaint, 1946; Consent Judgment, 1947). | H24: 58 | I24: WO, LA, CO | J24: 1934 | L24: 1947 | M24: 1 | N24: Y | O24: RF, RR | P24: 1 | Q24: 0
A25: 1934Vari | B25: Variable Condensers | C25: NAR New York | D25: Y | F25: X | G25: United States v. General Instrument Corp., 87 F. Supp. 157, 194 (D.N.J. 1949); United States v. General Instrument Corp., 115 F. Supp. 582 (D.N.J. 1953). | H25: 52 | I25: LA, WO | J25: 1934 | K25: 1949 | L25: 1953 | M25: 1 | N25: N | O25: RR | P25: 3 | Q25: 1
A26: 1935Airc | B26: Aircraft Instruments and Parts | C26: NAR New York | D26: Y | F26: X | G26: United States v. Bendix Aviation Corporation, CCH 1946-47 Trade Cases 57,444 (D.C.N.J. Civil No. 2531; Complaint, 1942, Consent Decree, 1946). | H26: 158 | I26: CO, WO | J26: 1935 | K26: 1942 | L26: 1946 | M26: 1 | N26: Y | O26: RR, DP | P26: 0 | Q26: 0
A27: 1937Male | B27: Male Hormones | C27: NAR New York | D27: Y | F27: X | G27: United States v. Schering Corp., CCH Trade Regulation Reports, Supp. 1941-43, 52,729 (D.C.N.J. Civil No. 1919; Complaint and Consent Decree, Dec. 17, 1941). | H27: 157 | I27: CO, FJ, LA | J27: 1937 | K27: 1941 | L27: 1941 | N27: Y | P27: 0 | R27: No compulsory licensing
A28: 1937Park | B28: Parking Meters | C28: NAR Atlanta | D28: Y | F28: X | G28: United States v. Vehicular Parking, 54 F. Supp. 828, 831 (D. Delaware 1944); CCH 1944-45 Trade Cases 57,226. | H28: 89 | I28: FJ | J28: 1937 | K28: 1944 | L28: 1946 | N28: N | O28: RR | P28: 4
A29: 1937Stam | B29: Stamped Metal Wheels | C29: NAR Chicago | D29: Y | F29: X | G29: United States v. Kelsey-Hayes Wheel Co. (E.D.Mich. Civil No. 10-655; Complaint, 1951). | H29: 61 | I29: ME | J29: 1937 | L29: 1955 | M29: 0 | N29: N | O29: RR | P29: 11 | Q29: 1
A30: 1937Wrin | B30: Wrinkle Finishes | C30: NAR Chicago | D30: Y | F30: X | G30: United States v. New Wrinkle, Inc., 1955 Trade Cases (C.C.H.) ¶ 68,203 (S.D. Ohio). | H30: 122 | I30: LA, WO | J30: 1937 | K30: 1952 | L30: 1955 | M30: 0 | N30: N | P30: 200 | Q30: 1
A31: 1938Drop | B31: Dropout Cutouts | C31: NAR Chicago | D31: Y | F31: X | G31: United States v. Line Material Co., 333 U.S. 287, 305 (1948). | H31: 51-52 | I31: ME, WO | J31: 1938 | K31: 1948 | L31: 1948 | M31: 0 | N31: N | O31: RR | P31: 10 | Q31: 0
A32: 1938Opht | B32: Ophthalmic Frames | C32: NAR Kansas City | D32: Y | F32: X | G32: United States v. American Optical Co., CCH 1948-49 Trade Cases 62,308 (S.D.N.Y. Civil No. 10-391; Complaint, 1940; Final Consent Judgment, 1948). | H32: 59-60 | I32: WO | J32: 1938 | L32: 1948 | M32: 0 | N32: N | O32: RR | P32: 14 | Q32: 1
A33: 1938Slip | B33: Furniture Slip Covers | C33: NADC | D33: Y | F33: X | G33: United States v. Krasnov, 143 F. Supp. 184 (E.D. Penn., 1956). | H33: 61 | I33: WO | J33: 1938 | K33: 1954 | L33: 1954 | M33: 0 | N33: N | P33: 2 | Q33: 1 | R33: Was forced to grant licenses.
A34: 1942Tele | B34: Television | C34: NAR New York | D34: Y | F34: X | G34: United States v. Scophony Corp., CCH 1948-49 Trade Cases 62,238, 62,356, and 62,463 (S.D.N.Y. Civil No. 34-184; Complaint, 1945; Consent Decree, 1948 and 1949). | H34: 162 | I34: CO, FJ | J34: 1942 | L34: 1949 | N34: Y | O34: RR | P34: 0
A35: 1946Dayl | B35: Daylight Fluorescent Pigments | C35: NADC | D35: N | F35: X | G35: United States v. Switzer Brothers, Inc., Gantner & Mattern Co., The Firelure Corporation, The Sherwin-Williams Company, The Sherwin-Williams Company of California, Aberfoyle Manufacturing Company, Lawter Chemicals, Inc., Robert C. Switzer, Joseph L. Switzer, John O. Gantner, Jr., Eugene Burns, Gerald D. Stratford, and W. Bruce Beckley. | H35: 124-25 | I35: . | J35: 1949 | K35: 1953 | L35: 1953 | N35: N | O35: RR, RF | P35: 0 | R35: Need to obtain these documents again from chicago
A36: 1946Elas | B36: Elastic-Top Hosiery and Machinery | C36: NAR New York | D36: Y | F36: X | G36: United States v. The Davis Co., CCH 1952 Trade Cases 67,403 (S.D.N.Y. Civil No. 54-357; Complaint, 1949; Consent Judgment, 1952). See also: Baker-Cammack v. Davis., 181 F.2d 550 (1950). | H36: 60 | I36: CO, FJ | J36: 1946 | K36: 1949 | L36: 1952 | N36: N | O36: DP, RR | P36: 0
A37: 1948Trac | B37: Tractor Cabs | C37: NAR Chicago | D37: N | F37: X | G37: United States v. Bearing Distributors Co., CCH 1952-53 Trade Cases 67,595 (W.D. Mo. Civil No. 6895; Complaint, 1951; Consent Decree, 1953). | H37: 60-61 | I37: WO | J37: 1948 | K37: 1951 | L37: 1953 | N37: N | O37: RR | P37: 0
D39: =COUNTIF(D2:D34,"Y") -> 32 | E39: =COUNTIF(E2:E37,"Y") -> 0 | F39: =COUNTIF(F2:F37,"X") -> 36 | J39: =AVERAGE(J2:J37) -> 1933.2778 | L39: =AVERAGE(L2:L37) -> 1949.6944 | O39: =36-COUNTBLANK(O2:O37) -> 31
A40: Notes
A41: Document type abbreviations: LA=License Agreement; FJ/WO=Final Judgment; ME=Memorandum; CC=CCH Written Opinion, CO=Complaint
...

Sheet pool_chars.csv
A1: pool_id | B1: start_year | C1: end_year | D1: Duration | E1: pool_members | F1: foreign | G1: licensees | H1: num_pats | I1: lic_rest | J1: num_inital_pats | K1: grantbacks | L1: added | M1: prior_litigation
A2: ='Pool Index'!A2 -> 1919Equi | B2: ='Pool Index'!J2 -> 1919 | C2: ='Pool Index'!L2 -> 1953 | D2: =C2-B2 -> 34 | E2: =18-COUNTBLANK(Firms!B2:S2) -> 10 | F2: ='Pool Index'!N2 -> Y | G2: ='Pool Index'!P2 -> 0 | H2: =COUNTIF('all_pats.csv'!A:A,'pool_chars.csv'!A2) -> 0 | I2: . | J2: =COUNTIF('pre_pool_pats.csv'!A:A,'pool_chars.csv'!A2) -> 0 | K2: . | M2: ='Pool Index'!Q2 -> 0
A3: ='Pool Index'!A3 -> 1921Cast | B3: ='Pool Index'!J3 -> 1929 | C3: ='Pool Index'!L3 -> 1948 | D3: =C3-B3 -> 19 | E3: =18-COUNTBLANK(Firms!B3:S3) -> 2 | F3: ='Pool Index'!N3 -> N | G3: ='Pool Index'!P3 -> 4 | H3: =COUNTIF('all_pats.csv'!A:A,'pool_chars.csv'!A3) -> 0 | I3: 1 | J3: =COUNTIF('pre_pool_pats.csv'!A:A,'pool_chars.csv'!A3) -> 0 | K3: . | M3: ='Pool Index'!Q3 -> 0
A4: ='Pool Index'!A4 -> 1924Brak | B4: ='Pool Index'!J4 -> 1924 | C4: ='Pool Index'!L4 -> 1948 | D4: =C4-B4 -> 24 | E4: =18-COUNTBLANK(Firms!B4:S4) -> 6 | F4: ='Pool Index'!N4 -> N | G4: ='Pool Index'!P4 -> 21 | H4: =COUNTIF('all_pats.csv'!A:A,'pool_chars.csv'!A4) -> 0 | I4: 1 | J4: =COUNTIF('pre_pool_pats.csv'!A:A,'pool_chars.csv'!A4) -> 0 | K4: . | M4: ='Pool Index'!Q4 -> 0
A5: ='Pool Index'!A5 -> 1924Sand | B5: ='Pool Index'!J5 -> 1924 | C5: ='Pool Index'!L5 -> 1949 | D5: =C5-B5 -> 25 | E5: =18-COUNTBLANK(Firms!B5:S5) -> 3 | F5: ='Pool Index'!N5 -> N | G5: ='Pool Index'!P5 -> 0 | H5: =COUNTIF('all_pats.csv'!A:A,'pool_chars.csv'!A5) -> 0 | I5: 1 | J5: =COUNTIF('pre_pool_pats.csv'!A:A,'pool_chars.csv'!A5) -> 0 | K5: . | M5: ='Pool Index'!Q5 -> 0
A6: ='Pool Index'!A6 -> 1925Vent | B6: ='Pool Index'!J6 -> 1925 | C6: ='Pool Index'!L6 -> 1946 | D6: =C6-B6 -> 21 | E6: =18-COUNTBLANK(Firms!B6:S6) -> 2 | F6: ='Pool Index'!N6 -> N | G6: ='Pool Index'!P6 -> 4 | H6: =COUNTIF('all_pats.csv'!A:A,'pool_chars.csv'!A6) -> 0 | I6: 0 | J6: =COUNTIF('pre_pool_pats.csv'!A:A,'pool_chars.csv'!A6) -> 0 | K6: . | M6: ='Pool Index'!Q6 -> 0
A7: ='Pool Index'!A7 -> 1926Food | B7: ='Pool Index'!J7 -> 1926 | C7: ='Pool Index'!L7 -> 1954 | D7: =C7-B7 -> 28 | E7: =18-COUNTBLANK(Firms!B7:S7) -> 6 | F7: ='Pool Index'!N7 -> N | G7: ='Pool Index'!P7 -> 0 | H7: =COUNTIF('all_pats.csv'!A:A,'pool_chars.csv'!A7) -> 0 | I7: 0 | J7: =COUNTIF('pre_pool_pats.csv'!A:A,'pool_chars.csv'!A7) -> 0 | K7: . | M7: ='Pool Index'!Q7 -> 0
A8: ='Pool Index'!A8 -> 1927Airc | B8: ='Pool Index'!J8 -> 1927 | C8: ='Pool Index'!L8 -> 1945 | D8: =C8-B8 -> 18 | E8: =18-COUNTBLANK(Firms!B8:S8) -> 4 | F8: ='Pool Index'!N8 -> N | G8: ='Pool Index'!P8 -> 7 | H8: =COUNTIF('all_pats.csv'!A:A,'pool_chars.csv'!A8) -> 0 | I8: 0 | J8: =COUNTIF('pre_pool_pats.csv'!A:A,'pool_chars.csv'!A8) -> 0 | K8: . | M8: ='Pool Index'!Q8 -> 0
A9: ='Pool Index'!A9 -> 1927Flur | B9: ='Pool Index'!J9 -> 1927 | C9: ='Pool Index'!L9 -> 1954 | D9: =C9-B9 -> 27 | E9: =18-COUNTBLANK(Firms!B9:S9) -> 4 | F9: ='Pool Index'!N9 -> Y | G9: ='Pool Index'!P9 -> 11 | H9: =COUNTIF('all_pats.csv'!A:A,'pool_chars.csv'!A9) -> 0 | I9: . | J9: =COUNTIF('pre_pool_pats.csv'!A:A,'pool_chars.csv'!A9) -> 0 | K9: . | M9: ='Pool Index'!Q9 -> 0
A10: ='Pool Index'!A10 -> 1928Rail | B10: ='Pool Index'!J10 -> 1928 | C10: ='Pool Index'!L10 -> 1944 | D10: =C10-B10 -> 16 | E10: =18-COUNTBLANK(Firms!B10:S10) -> 3 | F10: ='Pool Index'!N10 -> N | G10: ='Pool Index'!P10 -> 10 | H10: =COUNTIF('all_pats.csv'!A:A,'pool_chars.csv'!A10) -> 0 | I10: 0 | J10: =COUNTIF('pre_pool_pats.csv'!A:A,'pool_chars.csv'!A10) -> 0 | K10: . | M10: ='Pool Index'!Q10 -> 0
A11: ='Pool Index'!A11 -> 1930Cabl | B11: ='Pool Index'!J11 -> 1930 | C11: ='Pool Index'!L11 -> 1948 | D11: =C11-B11 -> 18 | E11: =18-COUNTBLANK(Firms!B11:S11) -> 6 | F11: ='Pool Index'!N11 -> Y | G11: ='Pool Index'!P11 -> 0 | H11: =COUNTIF('all_pats.csv'!A:A,'pool_chars.csv'!A11) -> 294 | I11: 0 | J11: =COUNTIF('pre_pool_pats.csv'!A:A,'pool_chars.csv'!A11) -> 73 | K11: ='Pool Index'!M11 -> 1 | L11: =H11-J11 -> 221 | M11: ='Pool Index'!Q11 -> 0
A12: ='Pool Index'!A12 -> 1930Wate | B12: ='Pool Index'!J12 -> 1930 | C12: ='Pool Index'!L12 -> 1951 | D12: =C12-B12 -> 21 | E12: =18-COUNTBLANK(Firms!B12:S12) -> 4 | F12: ='Pool Index'!N12 -> Y | G12: ='Pool Index'!P12 -> 0 | H12: =COUNTIF('all_pats.csv'!A:A,'pool_chars.csv'!A12) -> 130 | I12: 0 | J12: =COUNTIF('pre_pool_pats.csv'!A:A,'pool_chars.csv'!A12) -> 4 | K12: ='Pool Index'!M12 -> 1 | L12: =H12-J12 -> 126 | M12: ='Pool Index'!Q12 -> 0
A13: ='Pool Index'!A13 -> 1931Fuel | B13: ='Pool Index'!J13 -> 1931 | C13: ='Pool Index'!L13 -> 1942 | D13: =C13-B13 -> 11 | E13: =18-COUNTBLANK(Firms!B13:S13) -> 4 | F13: ='Pool Index'!N13 -> Y | G13: ='Pool Index'!P13 -> 0 | H13: =COUNTIF('all_pats.csv'!A:A,'pool_chars.csv'!A13) -> 171 | I13: 1 | J13: =COUNTIF('pre_pool_pats.csv'!A:A,'pool_chars.csv'!A13) -> 22 | K13: ='Pool Index'!M13 -> 1 | L13: =H13-J13 -> 149 | M13: ='Pool Index'!Q13 -> 1
A14: ='Pool Index'!A14 -> 1931Mill | K14: . | M14: ='Pool Index'!Q14 -> 0
A15: ='Pool Index'!A15 -> 1932Phar | B15: ='Pool Index'!J15 -> 1932 | C15: ='Pool Index'!L15 -> 1945 | D15: =C15-B15 -> 13 | E15: =18-COUNTBLANK(Firms!B15:S15) -> 2 | F15: ='Pool Index'!N15 -> Y | G15: ='Pool Index'!P15 -> 0 | H15: =COUNTIF('all_pats.csv'!A:A,'pool_chars.csv'!A15) -> 110 | I15: 0 | J15: =COUNTIF('pre_pool_pats.csv'!A:A,'pool_chars.csv'!A15) -> 5 | K15: ='Pool Index'!M15 -> 1 | L15: =H15-J15 -> 105 | M15: ='Pool Index'!Q15 -> 0
A16: ='Pool Index'!A16 -> 1932Rail | B16: ='Pool Index'!J16 -> 1932 | C16: ='Pool Index'!L16 -> 1947 | D16: =C16-B16 -> 15 | E16: =18-COUNTBLANK(Firms!B16:S16) -> 3 | F16: ='Pool Index'!N16 -> N | G16: ='Pool Index'!P16 -> 9 | H16: =COUNTIF('all_pats.csv'!A:A,'pool_chars.csv'!A16) -> 13 | I16: 1 | J16: =COUNTIF('pre_pool_pats.csv'!A:A,'pool_chars.csv'!A16) -> 6 | K16: ='Pool Index'!M16 -> 1 | L16: =H16-J16 -> 7 | M16: ='Pool Index'!Q16 -> 0
A17: ='Pool Index'!A17 -> 1932Text | B17: ='Pool Index'!J17 -> 1932 | C17: ='Pool Index'!L17 -> 1950 | D17: =C17-B17 -> 18 | E17: =18-COUNTBLANK(Firms!B17:S17) -> 2 | F17: ='Pool Index'!N17 -> N | G17: ='Pool Index'!P17 -> 0 | H17: =COUNTIF('all_pats.csv'!A:A,'pool_chars.csv'!A17) -> 218 | I17: 0 | J17: =COUNTIF('pre_pool_pats.csv'!A:A,'pool_chars.csv'!A17) -> 39 | K17: ='Pool Index'!M17 -> 0 | L17: =H17-J17 -> 179 | M17: ='Pool Index'!Q17 -> 0
A18: ='Pool Index'!A18 -> 1933Hydr | B18: ='Pool Index'!J18 -> 1933 | C18: ='Pool Index'!L18 -> 1952 | D18: =C18-B18 -> 19 | E18: =18-COUNTBLANK(Firms!B18:S18) -> 2 | F18: ='Pool Index'!N18 -> N | G18: ='Pool Index'!P18 -> 0 | H18: =COUNTIF('all_pats.csv'!A:A,'pool_chars.csv'!A18) -> 46 | I18: . | J18: =COUNTIF('pre_pool_pats.csv'!A:A,'pool_chars.csv'!A18) -> 3 | K18: ='Pool Index'!M18 -> 1 | L18: =H18-J18 -> 43 | M18: ='Pool Index'!Q18 -> 0
A19: ='Pool Index'!A19 -> 1933Mach | B19: ='Pool Index'!J19 -> 1933 | C19: ='Pool Index'!L19 -> 1955 | D19: =C19-B19 -> 22 | E19: =18-COUNTBLANK(Firms!B19:S19) -> 5 | F19: ='Pool Index'!N19 -> N | G19: ='Pool Index'!P19 -> 0 | H19: =COUNTIF('all_pats.csv'!A:A,'pool_chars.csv'!A19) -> 9 | I19: . | J19: =COUNTIF('pre_pool_pats.csv'!A:A,'pool_chars.csv'!A19) -> 3 | K19: ='Pool Index'!M19 -> 1 | L19: =H19-J19 -> 6 | M19: ='Pool Index'!Q19 -> 0
A20: ='Pool Index'!A20 -> 1933Phil | B20: ='Pool Index'!J20 -> 1933 | C20: ='Pool Index'!L20 -> 1949 | D20: =C20-B20 -> 16 | E20: =18-COUNTBLANK(Firms!B20:S20) -> 2 | F20: ='Pool Index'!N20 -> N | G20: ='Pool Index'!P20 -> 28 | H20: =COUNTIF('all_pats.csv'!A:A,'pool_chars.csv'!A20) -> 26 | I20: 1 | J20: =COUNTIF('pre_pool_pats.csv'!A:A,'pool_chars.csv'!A20) -> 2 | K20: ='Pool Index'!M20 -> 1 | L20: =H20-J20 -> 24 | M20: ='Pool Index'!Q20 -> 0
A21: ='Pool Index'!A21 -> 1934Colo | B21: ='Pool Index'!J21 -> 1934 | C21: ='Pool Index'!L21 -> 1950 | D21: =C21-B21 -> 16 | E21: =18-COUNTBLANK(Firms!B21:S21) -> 2 | F21: ='Pool Index'!N21 -> N | G21: ='Pool Index'!P21 -> 0 | H21: =COUNTIF('all_pats.csv'!A:A,'pool_chars.csv'!A21) -> 162 | I21: 1 | J21: =COUNTIF('pre_pool_pats.csv'!A:A,'pool_chars.csv'!A21) -> 59 | K21: ='Pool Index'!M21 -> 1 | L21: =H21-J21 -> 103 | M21: ='Pool Index'!Q21 -> 0
A22: ='Pool Index'!A22 -> 1934Dry | B22: ='Pool Index'!J22 -> 1934 | C22: ='Pool Index'!L22 -> 1952 | D22: =C22-B22 -> 18 | E22: =18-COUNTBLANK(Firms!B22:S22) -> 4 | F22: ='Pool Index'!N22 -> N | G22: ='Pool Index'!P22 -> 0 | H22: =COUNTIF('all_pats.csv'!A:A,'pool_chars.csv'!A22) -> 58 | I22: 0 | J22: =COUNTIF('pre_pool_pats.csv'!A:A,'pool_chars.csv'!A22) -> 37 | K22: ='Pool Index'!M22 -> 1 | L22: =H22-J22 -> 21 | M22: ='Pool Index'!Q22 -> 0
A23: ='Pool Index'!A23 -> 1934Elec | B23: ='Pool Index'!J23 -> 1934 | C23: ='Pool Index'!L23 -> 1953 | D23: =C23-B23 -> 19 | E23: =18-COUNTBLANK(Firms!B23:S23) -> 2 | F23: ='Pool Index'!N23 -> Y | G23: ='Pool Index'!P23 -> 0 | H23: =COUNTIF('all_pats.csv'!A:A,'pool_chars.csv'!A23) -> 222 | I23: . | J23: =COUNTIF('pre_pool_pats.csv'!A:A,'pool_chars.csv'!A23) -> 30 | K23: ='Pool Index'!M23 -> 1 | L23: =H23-J23 -> 192 | M23: ='Pool Index'!Q23 -> 0
A24: ='Pool Index'!A24 -> 1934Leci | B24: ='Pool Index'!J24 -> 1934 | C24: ='Pool Index'!L24 -> 1947 | D24: =C24-B24 -> 13 | E24: =18-COUNTBLANK(Firms!B24:S24) -> 5 | F24: ='Pool Index'!N24 -> Y | G24: ='Pool Index'!P24 -> 1 | H24: =COUNTIF('all_pats.csv'!A:A,'pool_chars.csv'!A24) -> 63 | I24: 0 | J24: =COUNTIF('pre_pool_pats.csv'!A:A,'pool_chars.csv'!A24) -> 36 | K24: ='Pool Index'!M24 -> 1 | L24: =H24-J24 -> 27 | M24: ='Pool Index'!Q24 -> 0
A25: ='Pool Index'!A25 -> 1934Vari | B25: ='Pool Index'!J25 -> 1934 | C25: ='Pool Index'!L25 -> 1953 | D25: =C25-B25 -> 19 | E25: =18-COUNTBLANK(Firms!B25:S25) -> 3 | F25: ='Pool Index'!N25 -> N | G25: ='Pool Index'!P25 -> 3 | H25: =COUNTIF('all_pats.csv'!A:A,'pool_chars.csv'!A25) -> 74 | I25: 0 | J25: =COUNTIF('pre_pool_pats.csv'!A:A,'pool_chars.csv'!A25) -> 60 | K25: ='Pool Index'!M25 -> 1 | L25: =H25-J25 -> 14 | M25: ='Pool Index'!Q25 -> 1
A26: ='Pool Index'!A26 -> 1935Airc | B26: ='Pool Index'!J26 -> 1935 | C26: ='Pool Index'!L26 -> 1946 | D26: =C26-B26 -> 11 | E26: =18-COUNTBLANK(Firms!B26:S26) -> 18 | F26: ='Pool Index'!N26 -> Y | G26: ='Pool Index'!P26 -> 0 | H26: =COUNTIF('all_pats.csv'!A:A,'pool_chars.csv'!A26) -> 272 | I26: . | J26: =COUNTIF('pre_pool_pats.csv'!A:A,'pool_chars.csv'!A26) -> 92 | K26: ='Pool Index'!M26 -> 1 | L26: =H26-J26 -> 180 | M26: ='Pool Index'!Q26 -> 0
A27: ='Pool Index'!A27 -> 1937Male | K27: . | M27: ='Pool Index'!Q27 -> 0
A28: ='Pool Index'!A28 -> 1937Park | K28: . | M28: ='Pool Index'!Q28 -> 0
A29: ='Pool Index'!A29 -> 1937Stam | B29: ='Pool Index'!J29 -> 1937 | C29: ='Pool Index'!L29 -> 1955 | D29: =C29-B29 -> 18 | E29: =18-COUNTBLANK(Firms!B29:S29) -> 3 | F29: ='Pool Index'!N29 -> N | G29: ='Pool Index'!P29 -> 11 | H29: =COUNTIF('all_pats.csv'!A:A,'pool_chars.csv'!A29) -> 189 | I29: 1 | J29: =COUNTIF('pre_pool_pats.csv'!A:A,'pool_chars.csv'!A29) -> 90 | K29: ='Pool Index'!M29 -> 0 | L29: =H29-J29 -> 99 | M29: ='Pool Index'!Q29 -> 1
A30: ='Pool Index'!A30 -> 1937Wrin | B30: ='Pool Index'!J30 -> 1937 | C30: ='Pool Index'!L30 -> 1955 | D30: =C30-B30 -> 18 | E30: =18-COUNTBLANK(Firms!B30:S30) -> 2 | F30: ='Pool Index'!N30 -> N | G30: ='Pool Index'!P30 -> 200 | H30: =COUNTIF('all_pats.csv'!A:A,'pool_chars.csv'!A30) -> 77 | I30: . | J30: =COUNTIF('pre_pool_pats.csv'!A:A,'pool_chars.csv'!A30) -> 20 | K30: ='Pool Index'!M30 -> 0 | L30: =H30-J30 -> 57 | M30: ='Pool Index'!Q30 -> 1
A31: ='Pool Index'!A31 -> 1938Drop | B31: ='Pool Index'!J31 -> 1938 | C31: ='Pool Index'!L31 -> 1948 | D31: =C31-B31 -> 10 | E31: =18-COUNTBLANK(Firms!B31:S31) -> 2 | F31: ='Pool Index'!N31 -> N | G31: ='Pool Index'!P31 -> 10 | H31: =COUNTIF('all_pats.csv'!A:A,'pool_chars.csv'!A31) -> 2 | I31: 0 | J31: =COUNTIF('pre_pool_pats.csv'!A:A,'pool_chars.csv'!A31) -> 2 | K31: ='Pool Index'!M31 -> 0 | L31: =H31-J31 -> 0 | M31: ='Pool Index'!Q31 -> 0
A32: ='Pool Index'!A32 -> 1938Opht | B32: ='Pool Index'!J32 -> 1938 | C32: ='Pool Index'!L32 -> 1948 | D32: =C32-B32 -> 10 | E32: =18-COUNTBLANK(Firms!B32:S32) -> 4 | F32: ='Pool Index'!N32 -> N | G32: ='Pool Index'!P32 -> 14 | H32: =COUNTIF('all_pats.csv'!A:A,'pool_chars.csv'!A32) -> 22 | I32: 0 | J32: =COUNTIF('pre_pool_pats.csv'!A:A,'pool_chars.csv'!A32) -> 21 | K32: ='Pool Index'!M32 -> 0 | L32: =H32-J32 -> 1 | M32: ='Pool Index'!Q32 -> 1
A33: ='Pool Index'!A33 -> 1938Slip | B33: ='Pool Index'!J33 -> 1938 | C33: ='Pool Index'!L33 -> 1954 | D33: =C33-B33 -> 16 | E33: =18-COUNTBLANK(Firms!B33:S33) -> 2 | F33: ='Pool Index'!N33 -> N | G33: ='Pool Index'!P33 -> 2 | H33: =COUNTIF('all_pats.csv'!A:A,'pool_chars.csv'!A33) -> 2 | I33: . | J33: =COUNTIF('pre_pool_pats.csv'!A:A,'pool_chars.csv'!A33) -> 2 | K33: ='Pool Index'!M33 -> 0 | L33: =H33-J33 -> 0 | M33: ='Pool Index'!Q33 -> 1
A34: ='Pool Index'!A34 -> 1942Tele | B34: ='Pool Index'!J34 -> 1942 | C34: ='Pool Index'!L34 -> 1949 | D34: =C34-B34 -> 7 | E34: =18-COUNTBLANK(Firms!B34:S34) -> 3 | F34: ='Pool Index'!N34 -> Y | G34: ='Pool Index'!P34 -> 0 | H34: =COUNTIF('all_pats.csv'!A:A,'pool_chars.csv'!A34) -> 0 | I34: 0 | J34: =COUNTIF('pre_pool_pats.csv'!A:A,'pool_chars.csv'!A34) -> 0 | K34: . | M34: ='Pool Index'!Q34 -> 0
A35: ='Pool Index'!A35 -> 1946Dayl | B35: ='Pool Index'!J35 -> 1949 | C35: ='Pool Index'!L35 -> 1953 | D35: =C35-B35 -> 4 | E35: =18-COUNTBLANK(Firms!B35:S35) -> 6 | F35: ='Pool Index'!N35 -> N | G35: ='Pool Index'!P35 -> 0 | H35: =COUNTIF('all_pats.csv'!A:A,'pool_chars.csv'!A35) -> 0 | I35: 1 | J35: =COUNTIF('pre_pool_pats.csv'!A:A,'pool_chars.csv'!A35) -> 0 | K35: . | M35: ='Pool Index'!Q35 -> 0
A36: ='Pool Index'!A36 -> 1946Elas | B36: ='Pool Index'!J36 -> 1946 | C36: ='Pool Index'!L36 -> 1952 | D36: =C36-B36 -> 6 | E36: =18-COUNTBLANK(Firms!B36:S36) -> 3 | F36: ='Pool Index'!N36 -> N | G36: ='Pool Index'!P36 -> 0 | H36: =COUNTIF('all_pats.csv'!A:A,'pool_chars.csv'!A36) -> 0 | I36: 0 | J36: =COUNTIF('pre_pool_pats.csv'!A:A,'pool_chars.csv'!A36) -> 0 | K36: . | M36: ='Pool Index'!Q36 -> 0
A37: ='Pool Index'!A37 -> 1948Trac | B37: ='Pool Index'!J37 -> 1948 | C37: ='Pool Index'!L37 -> 1953 | D37: =C37-B37 -> 5 | E37: =18-COUNTBLANK(Firms!B37:S37) -> 3 | F37: ='Pool Index'!N37 -> N | G37: ='Pool Index'!P37 -> 0 | H37: =COUNTIF('all_pats.csv'!A:A,'pool_chars.csv'!A37) -> 0 | I37: 0 | J37: =COUNTIF('pre_pool_pats.csv'!A:A,'pool_chars.csv'!A37) -> 0 | K37: . | M37: ='Pool Index'!Q37 -> 0
A39: Average | B39: =AVERAGE(B11:B33) -> 1933.95 | C39: =AVERAGE(C11:C33) -> 1950 | D39: =AVERAGE(D11:D33) -> 16.05 | E39: =AVERAGE(E11:E33) -> 3.85 | G39: =AVERAGE(G11:G33) -> 13.9 | H39: =AVERAGE(H11:H33) -> 108 | I39: =AVERAGE(I11:I33) -> 0.35714286 | J39: =AVERAGE(J11:J33) -> 30.3 | K39: =AVERAGE(K11:K33) -> 0.7 | L39: =AVERAGE(L11:L33) -> 77.7
A40: Median | B40: =MEDIAN(B11:B33) -> 1934 | C40: =MEDIAN(C11:C33) -> 1950 | D40: =MEDIAN(D11:D33) -> 17 | E40: =MEDIAN(E11:E33) -> 3 | G40: =MEDIAN(G11:G33) -> 0 | H40: =MEDIAN(H11:H33) -> 75.5 | I40: =MEDIAN(I11:I33) -> 0 | J40: =MEDIAN(J11:J33) -> 21.5 | K40: =MEDIAN(K11:K33) -> 1 | L40: =MEDIAN(L11:L33) -> 50

Sheet antitrust violations
A1: PoolID | B1: Technology | C1: Antitrust Violations | D1: Remedies | E1: Case
A2: 1919Equi | B2: Electrical Equipment | E2: ='Pool Index'!G2 -> United States v. General Electric Co., CCH 1952-53 Trade Cases 67,585 (D.C.N.J. Civil No. 45-75-C; Complaint, 1945; Final Consent Judgment, 1953).
A3: 1921Cast | B3: Cast Iron Pipes | E3: ='Pool Index'!G3 -> United States v. United States Pipe and Foundry Co., CCH 1948-49 Trade Cases 62,285 (D.N.J. Civil No. 10772; Complaint, 1947; Consent Decree, 1948).
A4: 1924Brak | B4: Braking Systems | E4: ='Pool Index'!G4 -> United States v. Bendix Aviation Corp., Westinghouse Air Brake Co., et al., CCH 1948-49 Trade Cases 62,349 (S.D.N.Y. Civil No. 44-284; Complaint , 1947; Consent Judgment re Westinghouse, 1948).
A5: 1924Sand | B5: Sand Spun Pipes | E5: ='Pool Index'!G5 -> United States v. Sand Spun Patents Corp., 1948-1949 Trade Cases 62,462 (D.N.J. Civil No. 125-49; Complaint, 1949; Consent Judgment, 1949).
A6: 1925Vent | B6: Ventilating Air Filters | E6: ='Pool Index'!G6 -> United States v. American Air Filter Co., CCH 1946-47 Trade Cases 57,492 (W.D. Ky. Civil No. 574; Complaint, 1943; Consent Judgment, 1946).
A7: 1926Food | B7: Peach Pitting Machinery | E7: ='Pool Index'!G7 -> United States v. Food Machinery and Chemical Corp. (N.D. Calif. Civil No. 29308-G; Complaint, 1949).
A8: 1927Airc | B8: Air-conditioning Equipment | E8: ='Pool Index'!G8 -> United States v. Auditorium Conditioning Corp., CCH 1944-45 Trade Cases 57,428 (S.D.N.Y. Civil No. 22-200; Complaint, 1943; Final Judgment, 1945).
A9: 1927Flur | B9: Glass Lamps | E9: ='Pool Index'!G9 -> United States v. General Electric Co., Corning Glass Works, et al., CCH 1946-47 Trade Cases 57,448 (D.N.J. Civil No. 2590; Complaint, 1942; Consent Decree re Corning, 1946).
A10: 1928Rail | B10: Rail Joint Bars | E10: ='Pool Index'!G10 -> United States v. Rail Joint Co., CCH 1946-47 Trade Cases ¶ 57,469, (N. D. Ill. Civil No. 43-C-1295; Complaint, 1943; Final Judgment, 1944); McKenna Process Company of Illinois, Appellee, v. Blatchford Corporation, Appellant, Gen. No. 9,464, APPELLATE COURT OF ILLINOIS, SECOND DISTRICT, 304 Ill. App. 101; 25 N.E.2d 916; 1940 Ill. App. LEXIS 921.
A11: 1930Cabl | B11: High-Tension Cables | C11: Price-fixing; Denied licenses to competitors; Divided world markets | D11: Restrictive agreements cancelled; Compulsory RAND licensing | E11: ='Pool Index'!G11 -> United States v. General Cable Corp., CCH 1948-49 Trade Cases 62,300 (S.D.N.Y. Civil No. 40-76; Complaint, 1947; Consent Judgment, 1948).
A12: 1930Wate | B12: Water Conditioning Apparatus | C12: Denied licenses to competitors; Divided world markets | D12: Restrictive agreements cancelled; Ccompulsory RAND and royalty-free licensing | E12: ='Pool Index'!G12 -> United States v. The Permutit Company and W. Spencer Robertson, CCH 1950-51 Trade Cases 62,888 (S.D.N.Y. Civil No. 32-394; Complaint, 1945; Consent Judgment, 1951).
A13: 1931Fuel | B13: Fuel Injection Equipment | C13: Denied licenses to competitors; Divided world markets; | D13: Restricitve agreements cancelled; Compulsory RAND licensing | E13: ='Pool Index'!G13 -> United States v. American Bosch Corp., CCH 1948-49 Trade Cases 62,284 (S.D.N.Y. Civil No. 20-164; Complaint and Consent Decree, Dec. 29, 1942).
A14: 1931Mill | B14: Milling Machines | E14: ='Pool Index'!G14 -> United States v. Cincinnati Milling Machine Co., CCH 1953-54 Trade Cases 67,733 (E.D. Mich Civil No. 13401; Complaint and Consent Judgment, April 19, 1954).
A15: 1932Phar | B15: Pharmaceuticals | C15: Price-fixing; Divided world markets | D15: Restrictive agreements cancelled; Compulsory royalty-free licensing | E15: ='Pool Index'!G15 -> United States v. Merck and Co., CCH 1944-45 Trade Cases 57,416 (D.C.N.J. Civil No. 3159; Complaint, 1943; Consent Decree, 1945).
A16: 1932Rail | B16: Railroad Springs | C16: Price-fixing; Allocating customers to specific manufacturers through bid-rigging | D16: Restrictive agreements cancelled; Ccompulsory RAND and royalty-free licensing | E16: ='Pool Index'!G16 -> United States v. American Locomotive Co., CCH 1945-47 Trade Cases ¶ 57,621 (N.D. Ind. Civil No. 545; Complaint, 1945; Consent Judgment, 1947).
A17: 1932Text | B17: Hosiery Machinery | C17: Denied sales of machinery to competitors of a pool member; Destroyed competing second-hand machinery | D17: Compulsory RAND and royalty-free licensing | E17: ='Pool Index'!G17 -> United States v. Textile Machine Works, CCH 1950-51 Trade Cases 62,709 (S.D.N.Y. Civil No. 43-671; Complaint, 1947; Fina; Judgment, 1950).
A18: 1933Hydr | B18: Hydraulic Oil Pumps | C18: Price-fixing; Denied licenses to competitors | D18: Triple damages awarded to a competitor, and alleged infringer, due to violation of Sherman Act | E18: ='Pool Index'!G18 -> Kobe, Inc. v. Dempsey Pump Co., 198 F.2d 416 (10th Cir. 1952); United States v. Kobe (N.D. Okla. Civil No. 2865; Complaint, 1951); also Civ. No. 2350.
A19: 1933Mach | B19: Machine Tools | C19: Allocated specific fields to pool members; Denied licenses to competitors | D19: None: pool dissolved by pool members due to internal litigation over the terms of their agreement | E19: ='Pool Index'!G19 -> United States v. Associated Patents, 134 F. Supp. 74 (E.D. Mich., 1955).
A20: 1933Phil | B20: Phillips Screws | C20: Price-fixing; Prevented licensees from producing competing screws | D20: Restrictive agreements cancelled; Compulsory RAND licensing | E20: ='Pool Index'!G20 -> United States v. Phillips Screw Co., 1949 Trade Cas. (C.C.H.) ¶62,394 (N.D. Ill.)
A21: 1934Colo | B21: Color Film | C21: Allocating color film production to Technicolor only | D21: Restrictive agreements cancelled; Ccompulsory RAND and royalty-free licensing | E21: ='Pool Index'!G21 -> United States v. Technicolor, Inc., CCH 1950-51 Trade Cases 2,586 (S.D. Calif. Civil No. 7507-M; Complaint, 1947; Consent Judgments, 1948 and 1950).
A22: 1934Dry | B22: Dry Ice | C22: Price-fixing; Allocated territories; Denied licenses to competitors; Conducted price wars against competitors | D22: Restrictive practices enjoined; Compulsory RAND licensing | E22: ='Pool Index'!G22 -> United States v. The Liquid Carbonic Corp., CCH Trade Cases 67,248 (E.D.N.Y. Civil No. 9179; Complaint, 1948; Final Judgment, 1952).
A23: 1934Elec | B23: Electric Generators | C23: Price-fixing; Divided world markets | D23: Restrictive agreements cancelled; Compulsory royalty-free licensing | E23: ='Pool Index'!G23 -> United States v. Westinghouse Electric Mfg. Co., CCH Current Trade Cases 67,501 (D.C.N.J. Civil No. 5152; Complaint, 1945; Consent Judgment, 1953).
A24: 1934Leci | B24: Lecithin | C24: Allocated domestic market shares; Divided world markets; Threatened competitors with litigation | D24: Restrictive agreements cancelled; Ccompulsory RAND and royalty-free licensing | E24: ='Pool Index'!G24 -> United States v. American Lecithin Co., CCH 1946-47 Trade Cases 57,542 (N.D. Ohio Civil No. 24115; Complaint, 1946; Consent Judgment, 1947).
A25: 1934Vari | B25: Variable Condensers | C25: Price-fixing; Denied licenses to competitors | D25: Dissolution of pool; Compulsory royalty-free licensing | E25: ='Pool Index'!G25 -> United States v. General Instrument Corp., 87 F. Supp. 157, 194 (D.N.J. 1949); United States v. General Instrument Corp., 115 F. Supp. 582 (D.N.J. 1953).
A26: 1935Airc | B26: Aircraft Instruments and Parts | C26: Divided world markets | D26: Restrictive agreements cancelled; Ccompulsory RAND and royalty-free licensing | E26: ='Pool Index'!G26 -> United States v. Bendix Aviation Corporation, CCH 1946-47 Trade Cases 57,444 (D.C.N.J. Civil No. 2531; Complaint, 1942, Consent Decree, 1946).
A27: 1937Male | B27: Male Hormones | E27: ='Pool Index'!G27 -> United States v. Schering Corp., CCH Trade Regulation Reports, Supp. 1941-43, 52,729 (D.C.N.J. Civil No. 1919; Complaint and Consent Decree, Dec. 17, 1941).
A28: 1937Park | B28: Parking Meters | E28: ='Pool Index'!G28 -> United States v. Vehicular Parking, 54 F. Supp. 828, 831 (D. Delaware 1944); CCH 1944-45 Trade Cases 57,226.
A29: 1937Stam | B29: Stamped Metal Wheels | C29: Price-fixing; Allocating distributors to manufacturers | D29: Restrictive practices enjoined; Compulsory RAND licensing | E29: ='Pool Index'!G29 -> United States v. Kelsey-Hayes Wheel Co. (E.D.Mich. Civil No. 10-655; Complaint, 1951).
A30: 1937Wrin | B30: Wrinkle Finishes | C30: Price-fixing | D30: Restricitve agreements cancelled; Compulsory RAND licensing | E30: ='Pool Index'!G30 -> United States v. New Wrinkle, Inc., 1955 Trade Cases (C.C.H.) ¶ 68,203 (S.D. Ohio).
A31: 1938Drop | B31: Dropout Cutouts | C31: Price-fixing | D31: Restrictive contracts cancelled; Compulsory RAND licensing | E31: ='Pool Index'!G31 -> United States v. Line Material Co., 333 U.S. 287, 305 (1948).
A32: 1938Opht | B32: Ophthalmic Frames | C32: Price-fixing; Restricting the sale of frames to certain wholesalers | D32: Restrictive agreements cancelled; Ccompulsory RAND and royalty-free licensing | E32: ='Pool Index'!G32 -> United States v. American Optical Co., CCH 1948-49 Trade Cases 62,308 (S.D.N.Y. Civil No. 10-391; Complaint, 1940; Final Consent Judgment, 1948).
A33: 1938Slip | B33: Furniture Slip Covers | C33: Price-fixing; Denied licenses to competitors unless forced to | D33: None: agreements dissolved prior to suit due to disagreement among pool members | E33: ='Pool Index'!G33 -> United States v. Krasnov, 143 F. Supp. 184 (E.D. Penn., 1956).
A34: 1942Tele | B34: Television | E34: ='Pool Index'!G34 -> United States v. Scophony Corp., CCH 1948-49 Trade Cases 62,238, 62,356, and 62,463 (S.D.N.Y. Civil No. 34-184; Complaint, 1945; Consent Decree, 1948 and 1949).
A35: 1946Dayl | B35: Daylight Fluorescent Pigments | E35: ='Pool Index'!G35 -> United States v. Switzer Brothers, Inc., Gantner & Mattern Co., The Firelure Corporation, The Sherwin-Williams Company, The Sherwin-Williams Company of California, Aberfoyle Manufacturing Company, Lawter Chemicals, Inc., Robert C. Switzer, Joseph L. Switzer, John O. Gantner, Jr., Eugene Burns, Gerald D. Stratford, and W. Bruce Beckley.
A36: 1946Elas | B36: Elastic-Top Hosiery and Machinery | E36: ='Pool Index'!G36 -> United States v. The Davis Co., CCH 1952 Trade Cases 67,403 (S.D.N.Y. Civil No. 54-357; Complaint, 1949; Consent Judgment, 1952). See also: Baker-Cammack v. Davis., 181 F.2d 550 (1950).
A37: 1948Trac | B37: Tractor Cabs | E37: ='Pool Index'!G37 -> United States v. Bearing Distributors Co., CCH 1952-53 Trade Cases 67,595 (W.D. Mo. Civil No. 6895; Complaint, 1951; Consent Decree, 1953).

Sheet Firms
A1: PoolID | B1: Firm 1 | C1: Firm 2 | D1: Firm 3 | E1: Firm 4 | F1: Firm 5 | G1: Firm 6 | H1: Firm 7 | I1: Firm 8 | J1: Firm 9 | K1: Firm 10
A2: ='Pool Index'!A2 -> 1919Equi | B2: GE/IGE | C2: Allgemeine Elektricitaets Gesellschaft | D2: Compagnie Francaise Pour l'Exploitations des Procedes Thomson-Houston (CFTH) | E2: Associated Electrical Industries (BTH a the time) | F2: Tokyo Shibaura Denki Kabushiki Kaisha | G2: Societe d'Electricite et de Mecanique | H2: Campagnia Generale di Elettricita | I2: Usines Carels Freres (Belgian firm) | J2: Franco Tosi Societa Anonima (Italian firm, acquired by Campagnia Generale di Elettricita later in 1919) | K2: French competitor of CFTH (together with CFTH and IGE organized a new company, Societe General de Constructions Electriques et Mecaniques which assumed rights of CFTH under 1919)
A3: ='Pool Index'!A3 -> 1921Cast | B3: U.S. Pipe and Foundry | C3: Centrifugal Pipe Corporation
A4: ='Pool Index'!A4 -> 1924Brak | B4: Bendix (formerly Bendix Corporation) | C4: GM | D4: Hydraulic Brake Company | F4: Wagner | G4: duPont | H4: Westinghouse
A5: ='Pool Index'!A5 -> 1924Sand | B5: American Cast Iron Pipe Company | C5: Florence Pipe Foundry and Machine Company | D5: Warren Foundry & Pipe Corporation
A6: ='Pool Index'!A6 -> 1925Vent | B6: Metal Textile Corporation | C6: Reed Air Filter Company
A7: ='Pool Index'!A7 -> 1926Food | B7: California Packing Corporation | C7: Anderson-Barngrover Manufacturing | D7: Mark Ewald | E7: Federal Pitter Company | F7: Benton Ballou Company | G7: Libby, McNeil & Libby
A8: ='Pool Index'!A8 -> 1927Airc | B8: Carrier Engineering Corporation | C8: Cooling & Air Conditioning Corporation (Sturtevant) | D8: American Blower | E8: York
A9: ='Pool Index'!A9 -> 1927Flur | B9: General Electric | C9: Westinghouse | D9: Corning Glass Works | E9: N.V. Phillips Gloeilampenfabriekan
A10: ='Pool Index'!A10 -> 1928Rail | B10: Woodings-Verona | C10: Rail Joint Company | D10: McKenna Process Company
A11: ='Pool Index'!A11 -> 1930Cabl | B11: GE | C11: General Cable Corporation | D11: Okonite-Callender Cable Company | E11: Phelps Dodge (own Phelps Dodge) | F11: Pirelli | G11: Protona
A12: ='Pool Index'!A12 -> 1930Wate | B12: Permutit Company | C12: United Water Softener | D12: Permutit Aktiengesellschaft | E12: Societe Anonyme Establishments Phillips
A13: ='Pool Index'!A13 -> 1931Fuel | B13: American Bosch Corporation | C13: Robert Bosch GMBH | D13: CAV Bosch | E13: Ateliers de Construction Lavelette
A14: ='Pool Index'!A14 -> 1931Mill | B14: Cincinnati Milling Machine Company | C14: Ingersoll | D14: Kearney
A15: ='Pool Index'!A15 -> 1932Phar | B15: Merck & Co. | C15: E. Merck
A16: ='Pool Index'!A16 -> 1932Rail | B16: American Locomotive Company | C16: Symington-Gould Corporation | D16: Universal Draft Gear Attachment Company
A17: ='Pool Index'!A17 -> 1932Text | B17: Textile Machine Works | C17: Berkshire Knitting Mills
A18: ='Pool Index'!A18 -> 1933Hydr | B18: Rodless (also held patents from Paul Yungling and Granville Knox, also secured a license under the Ira Humphreys and R. Crum patents) / Rodless Pump Company | C18: Old Kobe (President was Clarence J. Coberly)
A19: ='Pool Index'!A19 -> 1933Mach | B19: Lodge and Shipley Machine Tool Company | C19: Brown & Sharpe Manufacturing Company | D19: Lucas Machine Tool Company (became Mac Investment Company) | E19: Carlton Machine Tool Company | F19: Charles B. DeVlieg (DeVlieg Engineering Company)
A20: ='Pool Index'!A20 -> 1933Phil | B20: Henry Phillips | C20: American Screw Company
A21: ='Pool Index'!A21 -> 1934Colo | B21: Technicolor Motion Picture Corporation | C21: Eastman Kodak Company
A22: ='Pool Index'!A22 -> 1934Dry | B22: Liquid Carbonic Corporation | C22: Air Reduction Company/Pure | D22: Wyandotte Chemicals Corporation | E22: International Carbonic Engineering
A23: ='Pool Index'!A23 -> 1934Elec | B23: Siemens | C23: Westinhouse Electric & Manufacting Company
A24: ='Pool Index'!A24 -> 1934Leci | B24: Archer-Daniels-Midland | C24: Glidden Company | D24: Hansa | E24: Aarhus | F24: Ross and Rowe
A25: ='Pool Index'!A25 -> 1934Vari | B25: Radio Condenser Company | C25: General Instrument Corporation | D25: Dejur-Amsco Corporation
A26: ='Pool Index'!A26 -> 1935Airc | B26: Bendix Aviation Corporation | C26: Siemens A.M. | D26: Hakenfelde | E26: Ottico | F26: Tokyo Keiki Seisakusho | G26: Mitsui Bussan Kaishi | H26: Societe Generale des Carburateurs (Swiss firm) | I26: Zenith Carbureter Company (UK firm) | J26: Societe du Carbureteur Zenith (France) | K26: Societe Anonima Carburators Zenith (Italy) | L26: Solex Ltd (UK) | M26: Societe Anonyme Solex (French firm) | N26: Societa Anonima Carburatore Zenith (Italian firm) | O26: S. Smith & Sons | P26: Robert Bosch G.m.b.H. | Q26: Societe Anonyme Air-Equipment | R26: Joseph Lucas, Ltd (Rotax, Ltd) | S26: Northern Electric Company
A27: ='Pool Index'!A27 -> 1937Male | B27: Schering Corporation | C27: Roche-Organon | D27: Ciba Pharmaceutical Products | E27: Rare Chemicals | F27: Schering A.G. (German firm) | G27: N. V. Organon (Dutch firm)
A28: ='Pool Index'!A28 -> 1937Park | B28: Karpark (Joynt, Taylor, & Symington) | C28: Parkrite | D28: Dual
A29: ='Pool Index'!A29 -> 1937Stam | B29: Kelsey-Hayes Wheel Company | C29: The Budd Company | D29: Motor Wheel Corporation
A30: ='Pool Index'!A30 -> 1937Wrin | B30: The Kay & Ess Company / Kay & Ess Chemical Corporation | C30: Chadeloid Chemical Company
A31: ='Pool Index'!A31 -> 1938Drop | B31: Southern States Equipment Corporation | C31: Line Material Company
A32: ='Pool Index'!A32 -> 1938Opht | B32: American Optical | C32: Bausch & Lomb | D32: Ful-Vue Sales Company | E32: Uhlemann Optical
A33: ='Pool Index'!A33 -> 1938Slip | B33: Sure-Fit (Joseph A. Krasnov, Samuel Krasnov, and Seymour Krasnov) | C33: Comfy Manufacturing Company
A34: ='Pool Index'!A34 -> 1942Tele | B34: General Precision Equipment | C34: Television Productions | D34: Scophony Ltd.
A35: ='Pool Index'!A35 -> 1946Dayl | B35: Switzer Brothers | C35: Ganter & Mattern Co. | D35: Aberfoyle Manufacturing | E35: Gabbs Supply Co. | F35: Sherwin Williams | G35: Lawter Chemicals
A36: ='Pool Index'!A36 -> 1946Elas | B36: Davis & Son | C36: Scott & Williams | D36: Interwoven Stocking Company
A37: ='Pool Index'!A37 -> 1948Trac | B37: Cab-Ette Company | C37: Fort Dodge Tent and Awning Company | D37: Bearing Distributor Company

Sheet 1919Equi
A1: PoolID | B1: Listed under | C1: Patent | D1: Serial No. | E1: Application Date | F1: Application Date II | G1: Grant Date | H1: Assignee (if not, inventor name) | I1: Inventor Name | J1: Filed in country | K1: Filing date | L1: Comment
A2: 1919Equip | B2: Acquired Patents Exhibit "A" | C2: 2060672 | E2: 11340 | G2: 12002 | H2: General Electric Company | I2: Hugo Heymann | J2: Germany | K2: 11000
A3: 1919Equip | B3: Acquired Patents Exhibit "A" | C3: 2061410 | E3: 10812 | G3: 12009 | H3: General Electric Company | I3: Wilhelm Stäblein | J3: Germany | K3: 10463
A4: 1919Equip | B4: Acquired Patents Exhibit "A" | C4: 2062097 | E4: 11058 | G4: 12016 | H4: General Electric Company | I4: Herbert A. Lingard | J4: Great Britain | K4: 10702
A5: 1919Equip | B5: Acquired Patents Exhibit "A" | C5: 2064652 | E5: 11638 | G5: 12037 | H5: General Electric Company | I5: Cedric H. Flurscheim | J5: Great Britain | K5: 11297
A6: 1919Equip | B6: Acquired Patents Exhibit "A" | C6: 2068557 | E6: 11093 | G6: 12072 | H6: General Electric Company | I6: Maurice Masnou | J6: France | K6: 10738
A7: 1919Equip | B7: Acquired Patents Exhibit "A" | C7: 2068575 | E7: 11247 | G7: 12072 | H7: General Electric Company | I7: Georg Stark | J7: Germany | K7: 11016
A8: 1919Equip | B8: Acquired Patents Exhibit "A" | C8: 2070498 | E8: 11668 | G8: 12093 | H8: General Electric Company | I8: Herman Antoine Tournier | J8: France | K8: 11409
A9: 1919Equip | B9: Acquired Patents Exhibit "A" | C9: 2071176 | E9: 11715 | G9: 12100 | H9: General Electric Company | I9: Othmar Pollok | J9: Germany | K9: 11392
A10: 1919Equip | B10: Acquired Patents Exhibit "A" | C10: 2071965 | E10: 11197 | G10: 12107 | H10: General Electric Company | I10: Josef Biermanns | J10: Germany | K10: 10888
A11: 1919Equip | B11: Acquired Patents Exhibit "A" | C11: 2071967 | E11: 11917 | G11: 12107 | H11: General Electric Company | I11: Wilhelm Büngner | J11: Germany | K11: 11553
A12: 1919Equip | B12: Acquired Patents Exhibit "A" | C12: 2072733 | E12: 10211 | G12: 12114 | H12: General Electric Company | I12: Günther Dobke | J12: Germany | K12: 9854
A13: 1919Equip | B13: Acquired Patents Exhibit "A" | C13: 2075709 | E13: 10014 | G13: 12142 | H13: General Electric Company | I13: Jean Fallou | J13: France | K13: 9652
... A52: 1919Equip | B52: Acquired Patents Exhibit "A" | C52: 2095106 | E52: 12108 | G52: 12331 | H52: General Electric Company | I52: Max Stöhr | J52: Germany | K52: 11750
A53: 1919Equip | B53: Acquired Patents Exhibit "A" | C53: 2095120 | E53: 11844 | F53: (RN) 1937/7/29 | G53: 12331 | H53: General Electric Company | I53: Georges Belfils, Pierre G. Laurent | J53: France | K53: 11501
A54: 1919Equip | B54: Acquired Patents Exhibit "A" | C54: 2095132 | E54: 11750 | G54: 12331 | H54: General Electric Company | I54: Karl Hoffmann | J54: Germany | K54: 11390
A55: 1919Equip | B55: Acquired Patents Exhibit "A" | C55: 2095818 | E55: 11900 | G55: 12338 | H55: General Electric Company | I55: Tsutomu Kurokochi, Isao Miyamoto | J55: Japan | K55: 11565
A56: 1919Equip | B56: Acquired Patents Exhibit "A" | C56: 2095820 | E56: 11532 | G56: 12338 | H56: General Electric Company | I56: Walter Lenz | J56: Germany | K56: 11192
A57: 1919Equip | B57: Acquired Patents Exhibit "A" | C57: 2095821 | E57: 12156 | G57: 12338 | H57: General Electric Company | I57: Arnold Maas | J57: Germany | K57: 11799
A58: 1919Equip | B58: Acquired Patents Exhibit "A" | C58: 2096614 | E58: 11837 | G58: 12345 | H58: General Electric Company | I58: Friedrich Lehmhaus | J58: Germany | K58: 11490
A59: 1919Equip | B59: Acquired Patents Exhibit "A" | C59: 2098029 | E59: 10980 | G59: 12359 | H59: General Electric Company | I59: Herbert Dallmann | J59: Germany | K59: 10645
A60: 1919Equip | B60: Acquired Patents Exhibit "A" | C60: 2098035 | E60: 11981 | G60: 12359 | H60: General Electric Company | I60: Komao Fukushima | J60: Japan | K60: 11663
A61: 1919Equip | B61: Acquired Patents Exhibit "A" | C61: 2098064 | E61: 11196 | G61: 12359 | H61: General Electric Company | I61: Joachim Pfaffenberger | J61: Germany | K61: 10863
A62: 1919Equip | B62: Acquired Patents Exhibit "A" | C62: 2098212 | D62: (O) 111990 (Di) 139792 | E62: 12013 | F62: 12172 | G62: 12359 | H62: General Electric Company | I62: Kenneth J. R. Wilkinson | J62: Great Britain | K62: 11626
A63: 1919Equip | B63: Acquired Patents Exhibit "A" | C63: 2098804 | E63: 11870 | G63: 12366 | H63: General Electric Company | I63: Herbert Hootz | J63: Germany | K63: 11512
A64: 1919Equip | B64: Acquired Patents Exhibit "A" | C64: 2099568 | E64: 11662 | G64: 12373 | H64: General Electric Company | I64: Friedrich Metzger | J64: Germany | K64: 11306
A65: 1919Equip | B65: Acquired Patents Exhibit "A" | C65: 2099576 | E65: 11918 | G65: 12373 | H65: General Electric Company | I65: Carl Schiebeler | J65: Germany | K65: 11585
A66: 1919Equip | B66: Acquired Patents Exhibit "A" | C66: 2100833 | E66: 11735 | G66: 12387 | H66: General Electric Company | I66: Waldemar Brückel, Karl Haas | J66: Germany | K66: 11381
A67: 1919Equip | B67: Acquired Patents Exhibit "A" | C67: 2101676 | E67: 11908 | G67: 12394 | H67: General Electric Company | I67: Werner Guilhauman | J67: Germany | K67: 11584
A68: 1919Equip | B68: Acquired Patents Exhibit "A" | C68: 2102400 | E68: 11331 | G68: 12401 | H68: General Electric Company | I68: Otto Wünsche | J68: Germany | K68: 10986
A69: 1919Equip | B69: Acquired Patents Exhibit "A" | C69: 2102768 | E69: 11694 | G69: 12408 | H69: General Electric Company | I69: Henry Trencham, Harold Ernest Cox | J69: Great Britain | K69: 11329
A70: 1919Equip | B70: Acquired Patents Exhibit "A" | C70: 2104629 | E70: 12607 | G70: 12422 | H70: General Electric Company | I70: Raoul Willheim, Gerhard Frühauf | J70: Germany | K70: 11921
A71: 1919Equip | B71: Acquired Patents Exhibit "A" | C71: 2105362 | E71: 11533 | G71: 12429 | H71: General Electric Company | I71: Paul Nowak, Hermann Hofmeier | J71: Germany | K71: 11168
A72: 1919Equip | B72: Acquired Patents Exhibit "A" | C72: 2105363 | E72: 11604 | G72: 12429 | H72: General Electric Company | I72: Paul Nowak, Hermann Hofmeier | J72: Germany | K72: 11261
A73: 1919Equip | B73: Acquired Patents Exhibit "A" | C73: 2106582 | E73: 11759 | G73: 12443 | H73: General Electric Company | I73: George Wall | J73: Great Britain | K73: 11407
A74: 1919Equip | B74: Acquired Patents Exhibit "A" | C74: 2106692 | E74: 11891 | G74: 12443 | H74: General Electric Company | I74: Rowland Embleton | J74: Great Britain | K74: 11529
... A131: 1919Equip | B131: Acquired Patents Exhibit "A" | C131: 2135313 | E131: 12276 | G131: 12723 | H131: General Electric Company | I131: Ludwig Nolte | J131: Germany | K131: 11942
A132: 1919Equip | B132: Acquired Patents Exhibit "A" | C132: 2136227 | E132: 11501 | F132: (RN) 1938/5/19 | G132: 12730 | H132: General Electric Company | I132: Jean Augier, Pierre Gabriel Laurent | J132: France | K132: 11142
A133: 1919Equip | B133: Acquired Patents Exhibit "A" | C133: 2137133 | E133: 11126 | G133: 12737 | H133: General Electric Company | I133: Herbert Dallmann | J133: Germany | K133: 10771
A134: 1919Equip | B134: Acquired Patents Exhibit "A" | C134: 2137177 | E134: 12012 | G134: 12737 | H134: General Electric Company | I134: Paul Melchior | J134: Germany | K134: 11647
...

Sheet 1921Cast
A1: PoolID | B1: Patent | C1: Type of Compulsory Licensing | D1: Application Date | E1: Grant Date | F1: Assignee (Inventor)
A2: Patents listed in Exhibit A of Final Judgment, United States v. United States Pipe and Foundry Co., CCH 1948-49 Trade Cases 62,285 (D.N.J. Civil No. 10772; Complaint, 1947; Consent Decree, 1948):
A3: 1921Cast | B3: 1833025 | C3: DP | D3: 7151 | E3: 10189 | F3: Langenberg
A4: 1921Cast | B4: 1856863 | C4: DP | D4: 9114 | E4: 10350 | F4: Clark
A5: 1921Cast | B5: 1834128 | C5: DP | D5: 9129 | E5: 10196 | F5: Langenberg
A6: 1921Cast | B6: 1856874 | C6: DP | D6: 9531 | E6: 10350 | F6: Langenberg
A7: 1921Cast | B7: 1849072 | C7: DP | D7: 9650 | E7: 10301 | F7: Clark
A8: 1921Cast | B8: 1856890 | C8: DP | D8: 9828 | E8: 10350 | F8: Stokes
A9: 1921Cast | B9: 1845127 | C9: DP | D9: 9839 | E9: 10273 | F9: Clark
A10: 1921Cast | B10: 1897631 | C10: DP | D10: 9990 | E10: 10637 | F10: Clark
A11: 1921Cast | B11: 1899383 | C11: DP | D11: 9990 | E11: 10651 | F11: Clark
A12: 1921Cast | B12: 1890498 | C12: DP | D12: 10014 | E12: 10574 | F12: Daniel
A13: 1921Cast | B13: 1903220 | C13: DP | D13: 10190 | E13: 10679 | F13: Lemert
A14: 1921Cast | B14: 1953180 | C14: DP | D14: 10459 | E14: 11050 | F14: Langenberg
... A49: 1921Cast | B49: 2346861 | C49: DP | D49: 14402 | E49: 14718 | F49: Montgomery
A51: 1921Cast | B51: SN585467 | F51: Koch
A52: 1921Cast | B52: SN729219 | F52: Koch
A53: 1921Cast | B53: SN22375 | F53: Kurtz
A55: Notes
A56: Vaughan (pp. 123-24): "U.S. Pipe and Foundry, founded in 1899 as a consolidation of the old Addyston Pipe and Steel Company and other companies, became in 1931 the exclusive licensee in the United States for the centrifugal method of making cast-iron pipes. Between 1922 and 1946, it entered into lease-license agreements with four other companies under which it leased machines for producing centrifugal pipe and granted licenses to use the patents covering them...A consent decree in 1948 required the discontinuance of these restrictions, the transfer of title to pipe-manufacturing machines, and the dedication of fifty patents to the public."
A58: Firms: U.S. Pipe and Foundry, Centrifugal Pipe Corporation, International DeLavaud Manufacturing Corporation (wholly-owned subsidiary of Centrifugal), .
A59: Foreign firms: Yes
A60: Start year: 1921
A61: End year: 1948
A62: Grantbacks: Yes
A63: Independent licensing:
A64: Open licensing:
A65: Number of licensees: 4
A66: Compulsory licensing: DP
A67: Patent holding company: No
... A78: Licensees (though they were obliged to contribute patents):
A79: James B. Clow and Sons (National Cast Iron Pipe Company was acquired by Chow in 1929) | B79: 1922
A80: Lynchburg Foundry Company | B80: 1930
A81: Glamorgan Pipe and Foundry Company | B81: 1944
A82: McWane Cast Iron Pipe Company | B82: 1946
A84: Licensing restrictions
A85: Yes, see above: "each agreement involved the licensee assigning to U.S. Pipe all patents acquired by, not to manufacture any kind of pipe other than cast iron pipe."

Sheet 1924Brak
A1: PoolID | B1: Patent | C1: Type of Compulsory Licensing | D1: Serial No. | E1: Application Date | F1: Grant Date | G1: Assignee (if not, inventor name) | H1: Inventor Name
A2: These patents are listed in Schedule A of the Final Judgment, reasonable royalties:
A3: 1924Brak | B3: 1801818 | C3: RF | E3: 8268 | F3: 9972 | G3: The Westinghouse Air Brake Company | H3: Andrew C. Mathieson
A4: 1924Brak | B4: 1805655 | C4: RF | E4: 8457 | F4: 10000 | G4: The Westinghouse Air Brake Company | H4: Sidney G. Down
A5: 1924Brak | B5: 1879719 | C5: RF | E5: 8655 | F5: 10497 | G5: The Westinghouse Air Brake Company | H5: Carlton D. Stewart
A6: 1924Brak | B6: 1797395 | C6: RF | E6: 8681 | F6: 9944 | G6: The Westinghouse Air Brake Company | H6: Eugene L. Beecher
A7: 1924Brak | B7: 1895456 | C7: RF | E7: 8811 | F7: 10623 | G7: The Westinghouse Air Brake Company | H7: Clyde C. Farmer
A8: 1924Brak | B8: 1801823 | C8: RF | E8: 8839 | F8: 9972 | G8: The Westinghouse Air Brake Company | H8: Frank B. Thomas
A9: 1924Brak | B9: 1797431 | C9: RF | E9: 8846 | F9: 9944 | G9: The Westinghouse Air Brake Company | H9: Andrew C. Mathieson
A10: 1924Brak | B10: 1824062 | C10: RF | E10: 8980 | F10: 10126 | G10: The Westinghouse Air Brake Company | H10: Harry J. Winter
A11: 1924Brak | B11: 1786195 | C11: RF | E11: 9070 | F11: 9853 | G11: The Westinghouse Air Brake Company | H11: Jules Marie Joseph Dormoy
A12: 1924Brak | B12: 1887583 | C12: RF | E12: 9083 | F12: 10546 | G12: The Westinghouse Air Brake Company | H12: Sidney G. Down
A13: 1924Brak | B13: 1816076 | C13: RF | E13: 9141 | F13: 10070 | G13: The Westinghouse Air Brake Company | H13: Sidney G. Down
A14: 1924Brak | B14: 1824034 | C14: RF | E14: 9196 | F14: 10126 | G14: The Westinghouse Air Brake Company | H14: William M. Cady
... A34: 1924Brak | B34: 2426063 | C34: RF | E34: 14053 | F34: 15936 | G34: The Westinghouse Air Brake Company | H34: Roy R. Stevens
A35: 1924Brak | B35: 2426064 | C35: RF | D35: (O) 448167 (Di) 492987 | E35: 14053 | F35: 15936 | G35: The Westinghouse Air Brake Company | H35: Roy R. Stevens
A36: 1924Brak | B36: 2358643 | C36: RF | E36: 14090 | F36: 14872 | G36: The Westinghouse Air Brake Company | H36: Cecil S. Kelley
A37: 1924Brak | B37: 2366020 | C37: RF | D37: (O) 452950 (Di) 485115 | E37: 14090 | F37: 14970 | G37: The Westinghouse Air Brake Company | H37: John N. Good
A38: 1924Brak | B38: 2395180 | C38: RF | D38: (O) 452950 (Di) 512007 | E38: 14090 | F38: 15390 | G38: The Westinghouse Air Brake Company | H38: John N. Good
A39: 1924Brak | B39: 2407877 | C39: RF | E39: 14090 | F39: 15600 | G39: The Westinghouse Air Brake Company | H39: John N. Good
A40: 1924Brak | B40: 2355758 | C40: RF | D40: (O) 463892 (Di) 504702 | E40: 14181 | F40: 14837 | G40: The Westinghouse Air Brake Company | H40: Roy R. Stevens
A41: 1924Brak | B41: 2383278 | C41: RF | E41: 14181 | F41: 15208 | G41: The Westinghouse Air Brake Company | H41: Roy R. Stevens
A42: 1924Brak | B42: 2396448 | C42: RF | D42: (O) 463792 - 2383278(Di) 504701 | E42: 14181 | F42: 15411 | G42: The Westinghouse Air Brake Company | H42: Roy R. Stevens
A43: 1924Brak | B43: 2389058 | C43: RF | D43: (O) 463915 (Di) 580258 | E43: 14182 | F43: 15292 | G43: The Westinghouse Air Brake Company | H43: Cecil S. Kelley
A44: 1924Brak | B44: 2411732 | C44: RF | E44: 14182 | F44: 15670 | G44: The Westinghouse Air Brake Company | H44: Cecil S. Kelley
A45: 1924Brak | B45: 2402400 | C45: RF | E45: 14244 | F45: 15509 | G45: The Westinghouse Air Brake Company | H45: Ellis E. Hewitt, Robert E. Watson
A46: 1924Brak | B46: 2418129 | C46: RF | E46: 14244 | F46: 15796 | G46: The Westinghouse Air Brake Company | H46: Arthur G. Larson
A47: 1924Brak | B47: 2388357 | C47: RF | E47: 14273 | F47: 15285 | G47: The Westinghouse Air Brake Company | H47: Ellis E. Hewitt
A48: 1924Brak | B48: 2343661 | C48: RF | E48: 14334 | F48: 14676 | G48: The Westinghouse Air Brake Company | H48: William H. Glass
A49: 1924Brak | B49: 2381222 | C49: RF | D49: (O) 485114 (Di) 523656 | E49: 14364 | F49: 15194 | G49: The Westinghouse Air Brake Company | H49: Harry C. May
A50: 1924Brak | B50: 2438410 | C50: RF | E50: 14364 | F50: 16153 | G50: The Westinghouse Air Brake Company | H50: Harry C. May, East McKeesport
A51: 1924Brak | B51: 2382899 | C51: RF | D51: 485116 | E51: 14364 | F51: 15201 | G51: Universal Oil Products Company | H51: Robert J. Newman
A52: 1924Brak | B52: 2406264 | C52: RF | E52: 14386 | F52: 15572 | G52: The Westinghouse Air Brake Company | H52: Roy R. Stevens
